Workbook

Sheet BẮT ĐẦU
A1: JAVASCRIPT → REACTJS
A2: Lộ trình training intern · 32 buổi · 8 tuần · tập trung thực hành, evidence và code review
A4: TỔNG BUỔI | D4: ĐÃ HOÀN THÀNH | G4: TIẾN ĐỘ | J4: ĐIỂM TRUNG BÌNH
A5: =COUNTA('TIẾN ĐỘ 32 BUỔI'!$A$7:$A$38) -> 32 | D5: =COUNTIF('TIẾN ĐỘ 32 BUỔI'!$I$7:$I$38,"Hoàn thành") -> 0 | G5: =IFERROR(D5/A5,0) -> 0 | J5: =IFERROR(AVERAGEIF('TIẾN ĐỘ 32 BUỔI'!$J$7:$J$38,">0"),0) -> 0
A8: TIẾN ĐỘ THEO GIAI ĐOẠN
A9: Giai đoạn | B9: Kế hoạch | C9: Hoàn thành | D9: Tiến độ
A10: JS nền tảng | B10: =COUNTIF('TIẾN ĐỘ 32 BUỔI'!$C$7:$C$38,"GĐ1 · JS nền tảng") -> 8 | C10: =COUNTIFS('TIẾN ĐỘ 32 BUỔI'!$C$7:$C$38,"GĐ1 · JS nền tảng",'TIẾN ĐỘ 32 BUỔI'!$I$7:$I$38,"Hoàn thành") -> 0 | D10: =IFERROR(C10/B10,0) -> 0
A11: JS trên trình duyệt | B11: =COUNTIF('TIẾN ĐỘ 32 BUỔI'!$C$7:$C$38,"GĐ2 · JS trên trình duyệt") -> 8 | C11: =COUNTIFS('TIẾN ĐỘ 32 BUỔI'!$C$7:$C$38,"GĐ2 · JS trên trình duyệt",'TIẾN ĐỘ 32 BUỔI'!$I$7:$I$38,"Hoàn thành") -> 0 | D11: =IFERROR(C11/B11,0) -> 0
A12: React nền tảng | B12: =COUNTIF('TIẾN ĐỘ 32 BUỔI'!$C$7:$C$38,"GĐ3 · React nền tảng") -> 8 | C12: =COUNTIFS('TIẾN ĐỘ 32 BUỔI'!$C$7:$C$38,"GĐ3 · React nền tảng",'TIẾN ĐỘ 32 BUỔI'!$I$7:$I$38,"Hoàn thành") -> 0 | D12: =IFERROR(C12/B12,0) -> 0
A13: React ứng dụng | B13: =COUNTIF('TIẾN ĐỘ 32 BUỔI'!$C$7:$C$38,"GĐ4 · React ứng dụng") -> 8 | C13: =COUNTIFS('TIẾN ĐỘ 32 BUỔI'!$C$7:$C$38,"GĐ4 · React ứng dụng",'TIẾN ĐỘ 32 BUỔI'!$I$7:$I$38,"Hoàn thành") -> 0 | D13: =IFERROR(C13/B13,0) -> 0
A20: CÁCH TRIỂN KHAI
A21: 01 · TRƯỚC BUỔI HỌC | D21: 02 · TRONG BUỔI HỌC | G21: 03 · SAU BUỔI HỌC | J21: 04 · QUA BUỔI
A22: Intern đọc mục tiêu, search 3–5 từ khóa và ghi câu hỏi. Mentor chuẩn bị demo ngắn cùng bộ test case biên. | D22: 20' ôn bài · 45' concept · 75' hands-on · 20' review · 10' giao bài. Không code-along quá lâu. | G22: Intern nộp PR, ảnh/video và self-check. Mentor review theo tiêu chí đạt, không chỉ chấm code chạy được. | J22: Deliverable đạt · điểm từ 7/10 · intern giải thích được code · không còn blocker kiến thức cốt lõi.
A28: NHỊP HỌC ĐỀ XUẤT
A29: TUẦN 1–2 · JS CORE → TUẦN 3–4 · JS TRÊN TRÌNH DUYỆT → TUẦN 5–6 · REACT CORE → TUẦN 7–8 · REACT APP & FINAL PROJECT
A33: Bắt đầu ở sheet TIẾN ĐỘ 32 BUỔI để theo dõi. Mở các sheet 01–04 để xem giáo án chi tiết từng buổi. Sheet NĂNG LỰC dùng cho 1:1 hằng tuần; sheet ĐÁNH GIÁ dùng khi chấm final project.

Sheet TIẾN ĐỘ 32 BUỔI
A1: TIẾN ĐỘ 32 BUỔI
A2: Tracker gọn để mentor lọc theo tuần, giai đoạn và trạng thái. Nội dung giáo án chi tiết nằm ở các sheet 01–04.
A4: Ô màu vàng là dữ liệu cần cập nhật · Trạng thái và điểm sẽ tự phản ánh lên dashboard
A6: Buổi | B6: Tuần | C6: Giai đoạn | D6: Chủ đề | E6: Kết quả đầu ra | F6: Deliverable | G6: Giờ | H6: Hình thức | I6: Trạng thái | J6: Điểm | K6: Reviewer | L6: Ngày xong | M6: Blocker / Ghi chú
A7: 1 | B7: 1 | C7: GĐ1 · JS nền tảng | D7: Khởi động, công cụ & cách học | E7: Chạy được JavaScript trong browser/Node, dùng DevTools và Git theo workflow cơ bản. | F7: Repo chạy được, commit rõ nghĩa, PR có mô tả và không commit node_modules. | G7: 2.5 | H7: Workshop | I7: Chưa học
A8: 2 | B8: 1 | C8: GĐ1 · JS nền tảng | D8: Biến, kiểu dữ liệu & ép kiểu | E8: Chọn đúng const/let, dự đoán được kiểu và kết quả phép so sánh phổ biến. | F8: File solution.js kèm comment giải thích, tối thiểu 16/20 câu đúng. | G8: 2.5 | H8: Theory + Lab | I8: Chưa học
A9: 3 | B9: 1 | C9: GĐ1 · JS nền tảng | D9: Điều kiện, vòng lặp & debugging | E9: Viết luồng điều khiển rõ ràng và dùng debugger để tìm lỗi logic. | F9: PR có test case biên, ảnh breakpoint và ghi nguyên nhân lỗi. | G9: 2.5 | H9: Workshop | I9: Chưa học
A10: 4 | B10: 1 | C10: GĐ1 · JS nền tảng | D10: Function, scope, hoisting & closure | E10: Giải thích được execution context, scope và dùng closure trong bài toán thực tế. | F10: Unit-style assertions cho API cart; không mutate từ bên ngoài. | G10: 2.5 | H10: Theory + Lab | I10: Chưa học
A11: 5 | B11: 2 | C11: GĐ1 · JS nền tảng | D11: Array, String & thuật toán cơ bản | E11: Thao tác collection đúng, viết được bài xử lý dữ liệu nhỏ không phụ thuộc framework. | F11: Tất cả test mẫu pass; ghi rõ hàm nào mutate input. | G11: 2.5 | H11: Lab | I11: Chưa học
A12: 6 | B12: 2 | C12: GĐ1 · JS nền tảng | D12: Array methods & tư duy functional | E12: Biến đổi dữ liệu bằng map/filter/reduce, chọn method theo ý nghĩa thay vì nhồi reduce. | F12: Đọc pipeline từ trái sang phải; callback tên rõ; không dùng map chỉ để side effect. | G12: 2.5 | H12: Workshop | I12: Chưa học
A13: 7 | B13: 2 | C13: GĐ1 · JS nền tảng | D13: Object, destructuring, spread & JSON | E13: Mô hình hóa dữ liệu object và cập nhật bất biến ở mức nông. | F13: Input cũ không đổi; không crash khi thiếu field; nêu được giới hạn shallow copy. | G13: 2.5 | H13: Theory + Lab | I13: Chưa học
A14: 8 | B14: 2 | C14: GĐ1 · JS nền tảng | D14: Checkpoint 1 · Mini project JS Core | E14: Củng cố JS core qua bài toán dữ liệu, trình bày được quyết định code. | F14: Link repo + demo output + self-review theo rubric. | G14: 2.5 | H14: Checkpoint | I14: Chưa học
A15: 9 | B15: 3 | C15: GĐ2 · JS trên trình duyệt | D15: DOM selection & manipulation | E15: Tạo/cập nhật UI bằng DOM API, hiểu reflow ở mức thực hành. | F15: Video/GIF demo + PR; kiểm tra empty/loading/error UI giả lập. | G15: 2.5 | H15: Workshop | I15: Chưa học
A16: 10 | B16: 3 | C16: GĐ2 · JS trên trình duyệt | D16: Events, form & validation | E16: Xử lý tương tác, form và event propagation đúng cách. | F16: Không duplicate listener sau render; lỗi được xóa khi hợp lệ; submit không reload. | G16: 2.5 | H16: Workshop | I16: Chưa học
A17: 11 | B17: 3 | C17: GĐ2 · JS trên trình duyệt | D17: ES Modules, npm & cấu trúc project | E17: Tách module có ranh giới rõ và dùng package scripts/linter formatter. | F17: Cây thư mục + scripts + README setup; không commit dist/node_modules. | G17: 2.5 | H17: Workshop | I17: Chưa học
A18: 12 | B18: 3 | C18: GĐ2 · JS trên trình duyệt | D18: Async model, event loop & Promise | E18: Đọc đúng thứ tự async và viết chuỗi Promise có error path. | F18: Giải thích được vì sao output theo thứ tự; rejection luôn được xử lý. | G18: 2.5 | H18: Theory + Lab | I18: Chưa học
... A38: 32 | B38: 8 | C38: GĐ4 · React ứng dụng | D38: Demo, code review & kế hoạch phát triển | E38: Chứng minh năng lực qua demo, phản biện code và lập kế hoạch 30 ngày tiếp theo. | F38: Không có blocker; giải thích được code do mình viết; biết giới hạn và hướng cải thiện. | G38: 2.5 | H38: Demo + Assessment | I38: Chưa học

Sheet 01 JS NỀN TẢNG
A1: 01 · JAVASCRIPT NỀN TẢNG
A2: Tuần 1–2 · ngôn ngữ, tư duy xử lý dữ liệu và checkpoint JS Core
A4: 8 BUỔI · 20 GIỜ TRÊN LỚP · MỖI BUỔI CÓ SEARCH KEYWORDS + DELIVERABLE + TIÊU CHÍ ĐẠT
A6: BUỔI 01 · KHỞI ĐỘNG, CÔNG CỤ & CÁCH HỌC
A7: TUẦN 1 | C7: WORKSHOP | E7: 2.5 GIỜ | G7: MDN – JavaScript Introduction
A8: MỤC TIÊU | C8: Chạy được JavaScript trong browser/Node, dùng DevTools và Git theo workflow cơ bản.
A9: NỘI DUNG CHÍNH | C9: Cài Node LTS, VS Code, Git; phân biệt JavaScript engine/runtime; script tag vs console vs Node; đọc lỗi; Git clone/branch/commit/push; quy ước nộp bài.
A10: TỪ KHÓA SEARCH | C10: JavaScript runtime vs engine; Chrome DevTools console sources network; Node.js npm basics; git feature branch commit convention
A11: DEMO TRÊN LỚP | C11: Mentor tạo repo, chạy file JS bằng browser và Node, cố tình tạo SyntaxError/ReferenceError rồi debug.
A12: THỰC HÀNH | C12: Fork/clone repo training; tạo branch; viết 5 phép tính + log kiểu dữ liệu; sửa 3 lỗi mẫu; push PR đầu tiên.
A13: BÀI TẬP VỀ NHÀ | C13: Viết README môi trường + ảnh chụp DevTools + link PR.
A14: DELIVERABLE | C14: Repo chạy được, commit rõ nghĩa, PR có mô tả và không commit node_modules.
A15: TIÊU CHÍ ĐẠT | C15: Tự giải thích được browser vs Node; mở đúng tab DevTools; hoàn tất workflow Git không cần cầm tay.
A16: TÀI LIỆU | C16: MDN – JavaScript Introduction | E16: https://developer.mozilla.org/en-US/docs/Web/JavaScript/Guide/Introduction
A18: BUỔI 02 · BIẾN, KIỂU DỮ LIỆU & ÉP KIỂU
A19: TUẦN 1 | C19: THEORY + LAB | E19: 2.5 GIỜ | G19: MDN – Grammar and types
A20: MỤC TIÊU | C20: Chọn đúng const/let, dự đoán được kiểu và kết quả phép so sánh phổ biến.
A21: NỘI DUNG CHÍNH | C21: Primitive vs object; let/const; typeof; truthy/falsy; implicit/explicit coercion; == vs ===; null/undefined; NaN; template literal; naming.
A22: TỪ KHÓA SEARCH | C22: JavaScript primitive types; typeof null; truthy falsy table; type coercion; == vs ===; Number.isNaN; null vs undefined
A23: DEMO TRÊN LỚP | C23: Live predict-output 12 biểu thức, sau đó kiểm tra bằng console và giải thích từng kết quả.
A24: THỰC HÀNH | C24: Viết hàm normalizeUserInput chuyển input form sang name/age/active chuẩn; xử lý chuỗi rỗng, NaN, null.
A25: BÀI TẬP VỀ NHÀ | C25: 20 câu predict-output + refactor đoạn code dùng == và var.
A26: DELIVERABLE | C26: File solution.js kèm comment giải thích, tối thiểu 16/20 câu đúng.
A27: TIÊU CHÍ ĐẠT | C27: Không nhầm falsy với nullish; biết khi nào parse/convert dữ liệu ở boundary.
A28: TÀI LIỆU | C28: MDN – Grammar and types | E28: https://developer.mozilla.org/en-US/docs/Web/JavaScript/Guide/Grammar_and_types
A30: BUỔI 03 · ĐIỀU KIỆN, VÒNG LẶP & DEBUGGING
A31: TUẦN 1 | C31: WORKSHOP | E31: 2.5 GIỜ | G31: MDN – Control flow and error handling
A32: MỤC TIÊU | C32: Viết luồng điều khiển rõ ràng và dùng debugger để tìm lỗi logic.
A33: NỘI DUNG CHÍNH | C33: if/else, switch, ternary; for/while/for...of; break/continue; guard clause; console.table; breakpoint, step over/into, watch; đọc stack trace.
A34: TỪ KHÓA SEARCH | C34: JavaScript control flow; guard clause refactoring; for of vs for in; Chrome DevTools breakpoints watch call stack
A35: DEMO TRÊN LỚP | C35: Debug hàm tính phí giao hàng có 4 lỗi logic bằng breakpoint, không chỉ console.log.
A36: THỰC HÀNH | C36: Xây menu CLI nhỏ phân loại điểm và thống kê danh sách; áp dụng guard clause.
A37: BÀI TẬP VỀ NHÀ | C37: Giải 5 bài loop: FizzBuzz, tổng số chẵn, đếm ký tự, max thứ hai, nhóm theo trạng thái.
A38: DELIVERABLE | C38: PR có test case biên, ảnh breakpoint và ghi nguyên nhân lỗi.
A39: TIÊU CHÍ ĐẠT | C39: Code không lặp điều kiện thừa; chọn vòng lặp phù hợp; tìm được lỗi bằng call stack.
A40: TÀI LIỆU | C40: MDN – Control flow and error handling | E40: https://developer.mozilla.org/en-US/docs/Web/JavaScript/Guide/Control_flow_and_error_handling
A42: BUỔI 04 · FUNCTION, SCOPE, HOISTING & CLOSURE
A43: TUẦN 1 | C43: THEORY + LAB | E43: 2.5 GIỜ | G43: MDN – Functions
A44: MỤC TIÊU | C44: Giải thích được execution context, scope và dùng closure trong bài toán thực tế.
A45: NỘI DUNG CHÍNH | C45: Function declaration/expression/arrow; parameters/default/rest; return; pure function; lexical scope; hoisting; TDZ; closure; callback cơ bản.
...

Sheet 02 JS TRÌNH DUYỆT
A1: 02 · JAVASCRIPT TRÊN TRÌNH DUYỆT
A2: Tuần 3–4 · DOM, events, modules, async, HTTP và Vanilla JS App
A4: 8 BUỔI · 20 GIỜ TRÊN LỚP · MỖI BUỔI CÓ SEARCH KEYWORDS + DELIVERABLE + TIÊU CHÍ ĐẠT
A6: BUỔI 09 · DOM SELECTION & MANIPULATION
A7: TUẦN 3 | C7: WORKSHOP | E7: 2.5 GIỜ | G7: MDN – DOM scripting
A8: MỤC TIÊU | C8: Tạo/cập nhật UI bằng DOM API, hiểu reflow ở mức thực hành.
A9: NỘI DUNG CHÍNH | C9: DOM tree; querySelector; traversal; createElement; textContent vs innerHTML; classList; attributes; DocumentFragment; render function; XSS nhận biết.
A10: TỪ KHÓA SEARCH | C10: DOM tree querySelector createElement; textContent vs innerHTML security; DocumentFragment performance; DOM rendering patterns
A11: DEMO TRÊN LỚP | C11: Render bảng products từ array; empty state; cập nhật badge cart mà không reload.
A12: THỰC HÀNH | C12: Tạo component DOM thuần ProductCard và renderProducts(container, products).
A13: BÀI TẬP VỀ NHÀ | C13: Thêm search + sort UI cho Expense Tracker; không dùng innerHTML với dữ liệu người dùng.
A14: DELIVERABLE | C14: Video/GIF demo + PR; kiểm tra empty/loading/error UI giả lập.
A15: TIÊU CHÍ ĐẠT | C15: Không query DOM lặp vô ích; không nối HTML không an toàn; UI phản ánh đúng state.
A16: TÀI LIỆU | C16: MDN – DOM scripting | E16: https://developer.mozilla.org/en-US/docs/Learn_web_development/Core/Scripting/DOM_scripting
A18: BUỔI 10 · EVENTS, FORM & VALIDATION
A19: TUẦN 3 | C19: WORKSHOP | E19: 2.5 GIỜ | G19: MDN – Events
A20: MỤC TIÊU | C20: Xử lý tương tác, form và event propagation đúng cách.
A21: NỘI DUNG CHÍNH | C21: addEventListener; event object; bubbling/capturing; delegation; preventDefault; form submit; FormData; client validation; input/change; debounce concept.
A22: TỪ KHÓA SEARCH | C22: JavaScript event bubbling capturing; event delegation dynamic list; preventDefault form submit; FormData API; client side validation
A23: DEMO TRÊN LỚP | C23: Todo list có add/toggle/delete dùng một listener ở list; form hiển thị lỗi theo field.
A24: THỰC HÀNH | C24: Hoàn thiện form transaction: trim input, validation, inline error, keyboard submit.
A25: BÀI TẬP VỀ NHÀ | C25: Thêm filter buttons bằng event delegation; viết test checklist thao tác người dùng.
A26: DELIVERABLE | C26: Không duplicate listener sau render; lỗi được xóa khi hợp lệ; submit không reload.
A27: TIÊU CHÍ ĐẠT | C27: Giải thích target/currentTarget; dùng submit event thay vì click button.
A28: TÀI LIỆU | C28: MDN – Events | E28: https://developer.mozilla.org/en-US/docs/Learn_web_development/Core/Scripting/Events
A30: BUỔI 11 · ES MODULES, NPM & CẤU TRÚC PROJECT
A31: TUẦN 3 | C31: WORKSHOP | E31: 2.5 GIỜ | G31: MDN – JavaScript modules
A32: MỤC TIÊU | C32: Tách module có ranh giới rõ và dùng package scripts/linter formatter.
A33: NỘI DUNG CHÍNH | C33: import/export named/default; module scope; dependency graph; package.json; dependencies/devDependencies; npm scripts; Vite vanilla; ESLint/Prettier; .gitignore; env concept.
A34: TỪ KHÓA SEARCH | C34: ES modules named vs default export; package json scripts dependencies devDependencies; Vite vanilla JavaScript setup; ESLint flat config; .gitignore node_modules
A35: DEMO TRÊN LỚP | C35: Chuyển một file app.js 250 dòng thành data/service/ui/utils modules; chạy npm scripts.
A36: THỰC HÀNH | C36: Scaffold Vite vanilla; cấu hình lint/format; tách Expense Tracker thành modules.
A37: BÀI TẬP VỀ NHÀ | C37: PR phải pass npm run lint và npm run build; giải thích dependency direction.
A38: DELIVERABLE | C38: Cây thư mục + scripts + README setup; không commit dist/node_modules.
A39: TIÊU CHÍ ĐẠT | C39: Không circular import; module có nhiệm vụ rõ; app build production thành công.
A40: TÀI LIỆU | C40: MDN – JavaScript modules | E40: https://developer.mozilla.org/en-US/docs/Web/JavaScript/Guide/Modules
A42: BUỔI 12 · ASYNC MODEL, EVENT LOOP & PROMISE
A43: TUẦN 3 | C43: THEORY + LAB | E43: 2.5 GIỜ | G43: MDN – Using promises
A44: MỤC TIÊU | C44: Đọc đúng thứ tự async và viết chuỗi Promise có error path.
A45: NỘI DUNG CHÍNH | C45: Call stack; Web APIs; task/microtask; callback; Promise states; then/catch/finally; Promise.all/allSettled/race; error propagation.
...

Sheet 04 REACT ỨNG DỤNG
A1: 04 · REACT ỨNG DỤNG
A2: Tuần 7–8 · routing, shared state, server cache, testing và final project
A4: 8 BUỔI · 20 GIỜ TRÊN LỚP · MỖI BUỔI CÓ SEARCH KEYWORDS + DELIVERABLE + TIÊU CHÍ ĐẠT
A6: BUỔI 25 · ROUTING & LAYOUT ỨNG DỤNG
A7: TUẦN 7 | C7: WORKSHOP | E7: 2.5 GIỜ | G7: React Router – Start
A8: MỤC TIÊU | C8: Tạo điều hướng nhiều trang, nested layout và trang 404.
A9: NỘI DUNG CHÍNH | C9: Client-side routing; route config; Link/NavLink; params; search params; nested routes/outlet; navigation; protected-route concept; 404; URL as state.
A10: TỪ KHÓA SEARCH | C10: React Router nested routes outlet; useParams useSearchParams; NavLink active; 404 route; URL state filters
A11: DEMO TRÊN LỚP | C11: App có /products, /products/:id, /favorites; filter đồng bộ query string.
A12: THỰC HÀNH | C12: Thêm router cho project; direct refresh route được giải thích theo host config.
A13: BÀI TẬP VỀ NHÀ | C13: Breadcrumb nhỏ + not-found + back navigation hợp lý.
A14: DELIVERABLE | C14: Không dùng anchor gây full reload cho internal route; URL chia sẻ được trạng thái filter.
A15: TIÊU CHÍ ĐẠT | C15: Route modules/layout rõ; params không hợp lệ có fallback.
A16: TÀI LIỆU | C16: React Router – Start | E16: https://reactrouter.com/start/declarative/routing
A18: BUỔI 26 · USEREDUCER, CONTEXT & STATE DÙNG CHUNG
A19: TUẦN 7 | C19: DESIGN + LAB | E19: 2.5 GIỜ | G19: React – Reducer and Context
A20: MỤC TIÊU | C20: Quản lý state phức tạp có action rõ, chia sẻ vừa đủ bằng Context.
A21: NỘI DUNG CHÍNH | C21: Reducer pure; state/action; dispatch; initializer; reducer testing; Context provider/useContext; reducer+context; split state/dispatch; rerender caveat; when not to use context.
A22: TỪ KHÓA SEARCH | C22: React useReducer actions reducer pure; Context prop drilling; reducer context pattern; context rerender performance; state management decision
A23: DEMO TRÊN LỚP | C23: Chuyển cart nhiều transition sang reducer; tạo CartProvider + hooks.
A24: THỰC HÀNH | C24: Viết tests reducer bằng assertions; tích hợp favorites hoặc cart global.
A25: BÀI TẬP VỀ NHÀ | C25: Decision note: local state vs context vs server cache cho 6 loại dữ liệu.
A26: DELIVERABLE | C26: Reducer không side effect; action tên theo sự kiện; provider scope nhỏ nhất hợp lý.
A27: TIÊU CHÍ ĐẠT | C27: Không biến Context thành global dumping ground; consumer ngoài provider có error rõ.
A28: TÀI LIỆU | C28: React – Reducer and Context | E28: https://react.dev/learn/scaling-up-with-reducer-and-context
A30: BUỔI 27 · SERVER STATE, CACHE & TANSTACK QUERY
A31: TUẦN 7 | C31: WORKSHOP | E31: 2.5 GIỜ | G31: TanStack Query – React overview
A32: MỤC TIÊU | C32: Hiểu khác biệt client/server state và dùng query library cho fetch/cache/retry.
A33: NỘI DUNG CHÍNH | C33: Query key; query function; pending/error/success; cache/stale; refetch; mutation; invalidation; pagination concept; devtools; trade-off so với tự fetch Effect.
A34: TỪ KHÓA SEARCH | C34: TanStack Query React queryKey staleTime cacheTime gcTime; mutation invalidateQueries; server state vs client state; React Query pagination
A35: DEMO TRÊN LỚP | C35: Thay useEffect fetch list bằng useQuery; create favorite/product giả lập rồi invalidate.
A36: THỰC HÀNH | C36: Tích hợp query cho list/detail; đặt key factory nhỏ; hiển thị retry/error.
A37: BÀI TẬP VỀ NHÀ | C37: Viết bảng quyết định: useEffect fetch vs query library; mô tả staleTime cho app.
A38: DELIVERABLE | C38: Query key chứa dependency; không mirror data query vào state; mutation có feedback.
A39: TIÊU CHÍ ĐẠT | C39: Giải thích cache, stale và invalidation bằng ví dụ project.
A40: TÀI LIỆU | C40: TanStack Query – React overview | E40: https://tanstack.com/query/latest/docs/framework/react/overview
A42: BUỔI 28 · PERFORMANCE & RENDER OPTIMIZATION
A43: TUẦN 7 | C43: LAB + REVIEW | E43: 2.5 GIỜ | G43: React – useMemo
A44: MỤC TIÊU | C44: Đo trước khi tối ưu; nhận diện render thừa và dùng memoization đúng chỗ.
A45: NỘI DUNG CHÍNH | C45: React Profiler; render triggers; referential equality; memo; useMemo/useCallback; expensive calculation; list virtualization concept; code splitting/lazy/Suspense overview; premature optimization.
...

Sheet 03 REACT NỀN TẢNG
A1: 03 · REACT NỀN TẢNG
A2: Tuần 5–6 · component, props, state, forms, effects và custom hooks
A4: 8 BUỔI · 20 GIỜ TRÊN LỚP · MỖI BUỔI CÓ SEARCH KEYWORDS + DELIVERABLE + TIÊU CHÍ ĐẠT
A6: BUỔI 17 · REACT MENTAL MODEL, VITE, JSX & COMPONENT
A7: TUẦN 5 | C7: WORKSHOP | E7: 2.5 GIỜ | G7: React – Quick Start
A8: MỤC TIÊU | C8: Khởi tạo React app và mô tả UI bằng component thuần, JSX hợp lệ.
A9: NỘI DUNG CHÍNH | C9: Why React; declarative UI; render tree; component function; JSX rules; expressions; fragments; import assets; React DevTools; Vite React template.
A10: TỪ KHÓA SEARCH | C10: React declarative vs imperative UI; JSX rules expressions fragments; React render tree; Vite React setup; React DevTools
A11: DEMO TRÊN LỚP | C11: Chuyển ProductCard DOM thuần sang React component; quan sát render tree.
A12: THỰC HÀNH | C12: Scaffold app; tạo App/Header/ProductList/ProductCard từ dữ liệu tĩnh.
A13: BÀI TẬP VỀ NHÀ | C13: Tách landing page thành component tree và ghi lý do ranh giới.
A14: DELIVERABLE | C14: npm run dev/build chạy; component PascalCase; JSX không lỗi console.
A15: TIÊU CHÍ ĐẠT | C15: Component thuần theo props; không thao tác DOM trực tiếp để render UI.
A16: TÀI LIỆU | C16: React – Quick Start | E16: https://react.dev/learn
A18: BUỔI 18 · PROPS, COMPOSITION & CHILDREN
A19: TUẦN 5 | C19: WORKSHOP | E19: 2.5 GIỜ | G19: React – Passing props
A20: MỤC TIÊU | C20: Thiết kế component tái sử dụng bằng props và composition.
A21: NỘI DUNG CHÍNH | C21: Props read-only; destructuring/defaults; children; composition; one-way data flow; presentational vs container ở mức thực dụng; avoid boolean-prop explosion.
A22: TỪ KHÓA SEARCH | C22: React props read only; children composition patterns; one way data flow React; component API design; conditional children
A23: DEMO TRÊN LỚP | C23: Xây Button/Card/Modal/EmptyState APIs; so sánh component quá tổng quát và vừa đủ.
A24: THỰC HÀNH | C24: Refactor ProductCard để nhận actions/children; tạo reusable Section và Badge.
A25: BÀI TẬP VỀ NHÀ | C25: Viết Story-like demo page cho 6 trạng thái component không cần Storybook.
A26: DELIVERABLE | C26: Không mutate props; API component dễ đoán; layout không phụ thuộc dữ liệu global.
A27: TIÊU CHÍ ĐẠT | C27: Giải thích data flow parent→child và event callback child→parent.
A28: TÀI LIỆU | C28: React – Passing props | E28: https://react.dev/learn/passing-props-to-a-component
A30: BUỔI 19 · EVENTS, USESTATE & IMMUTABLE UPDATES
A31: TUẦN 5 | C31: THEORY + LAB | E31: 2.5 GIỜ | G31: React – Adding interactivity
A32: MỤC TIÊU | C32: Quản lý state local và cập nhật object/array không mutate.
A33: NỘI DUNG CHÍNH | C33: Event handlers; useState; render snapshot; batching; functional updater; controlled toggle; update object/array; state minimality; React Strict Mode nhận biết.
A34: TỪ KHÓA SEARCH | C34: React state as snapshot; batching state updates; functional state updater; updating arrays objects in state; useState common mistakes
A35: DEMO TRÊN LỚP | C35: Counter nhiều bước; cart add/remove/quantity; dùng React DevTools xem state.
A36: THỰC HÀNH | C36: Xây cart local với total derived; không lưu total vào state.
A37: BÀI TẬP VỀ NHÀ | C37: Bài sửa 8 bug mutate state/stale update; giải thích từng bug.
A38: DELIVERABLE | C38: UI cập nhật đúng nhiều lần liên tiếp; state cũ không bị mutate.
A39: TIÊU CHÍ ĐẠT | C39: Biết khi nào dùng prev =>; không đọc state mới ngay sau setter.
A40: TÀI LIỆU | C40: React – Adding interactivity | E40: https://react.dev/learn/adding-interactivity
A42: BUỔI 20 · CONDITIONAL RENDERING, LISTS & KEYS
A43: TUẦN 5 | C43: WORKSHOP | E43: 2.5 GIỜ | G43: React – Rendering lists
A44: MỤC TIÊU | C44: Render danh sách ổn định và chọn key đúng theo identity.
A45: NỘI DUNG CHÍNH | C45: &&/ternary/early return; list map; key identity; index key caveat; component state preservation/reset; loading/empty/error branches.
...

Sheet NĂNG LỰC
A1: NĂNG LỰC INTERN
A2: Chỉ đánh dấu Đạt khi intern tự làm lại được, giải thích được quyết định và có evidence cụ thể.
A4: TỔNG NĂNG LỰC | C4: ĐÃ ĐẠT | E4: ĐANG BỔ SUNG | G4: TỶ LỆ ĐẠT
A5: =COUNTA(A9:A44) -> 36 | C5: =COUNTIF(F9:F44,"Đạt") -> 0 | E5: =COUNTIF(F9:F44,"Đang bổ sung") -> 0 | G5: =IFERROR(C5/A5,0) -> 0
A8: Nhóm | B8: Năng lực | C8: Hành vi quan sát được | D8: Mức kỳ vọng | E8: Evidence gợi ý | F8: Trạng thái | G8: Tự tin /5 | H8: Ghi chú mentor
A9: Nền tảng | B9: Công cụ | C9: Chạy JS bằng browser và Node; dùng DevTools | D9: Tự làm | E9: Link PR buổi 1 | F9: Chưa đánh giá
A10: Nền tảng | B10: Git | C10: Branch/commit/push/PR và giải quyết conflict đơn giản | D10: Tự làm | E10: Repo training | F10: Chưa đánh giá
A11: JavaScript | B11: Kiểu dữ liệu | C11: Giải thích primitive, object, coercion, equality | D11: Giải thích + áp dụng | E11: Bài predict-output | F11: Chưa đánh giá
A12: JavaScript | B12: Control flow | C12: Guard clause, loop phù hợp, test case biên | D12: Áp dụng | E12: Bài buổi 3 | F12: Chưa đánh giá
A13: JavaScript | B13: Function | C13: Scope, hoisting, closure, callback | D13: Giải thích + áp dụng | E13: Cart closure | F13: Chưa đánh giá
A14: JavaScript | B14: Collection | C14: Array/string và map-filter-reduce | D14: Tự làm | E14: Data transformation | F14: Chưa đánh giá
A15: JavaScript | B15: Object | C15: Destructure/spread/optional chaining/JSON | D15: Tự làm | E15: Normalizer | F15: Chưa đánh giá
A16: JavaScript | B16: Immutability | C16: Không mutate input/state ngoài chủ đích | D16: Nhất quán | E16: Code review | F16: Chưa đánh giá
A17: Browser | B17: DOM | C17: Render/update DOM an toàn | D17: Tự làm | E17: Product list | F17: Chưa đánh giá
A18: Browser | B18: Events | C18: Bubbling, delegation, form submit | D18: Tự làm | E18: Form + dynamic list | F18: Chưa đánh giá
A19: Tooling | B19: Modules/npm | C19: Tách module, scripts, lint, build | D19: Tự làm | E19: Vite vanilla app | F19: Chưa đánh giá
A20: Async | B20: Event loop | C20: Dự đoán task/microtask | D20: Giải thích | E20: Quiz async | F20: Chưa đánh giá
... A44: Delivery | B44: Demo | C44: Walkthrough UI→state→API→test | D44: Tự tin | E44: Final demo | F44: Chưa đánh giá

Sheet ĐÁNH GIÁ
A1: ĐÁNH GIÁ FINAL PROJECT
A2: Nhập điểm 1–4 và evidence. File tự quy đổi về thang 100; mức đạt khuyến nghị từ 70 điểm.
A4: ĐIỂM QUY ĐỔI | E4: XẾP LOẠI
A5: =SUM(G12:G20) -> 0 | E5: =IF(A5>=85,"Tốt",IF(A5>=70,"Đạt",IF(A5>=50,"Cần bổ sung","Chưa đạt"))) -> Chưa đạt
A8: THANG ĐIỂM
A9: 4 · Vượt chuẩn, có evidence rõ | 3 · Đạt yêu cầu | 2 · Còn khoảng trống lớn | 1 · Chưa đạt chức năng hoặc không giải thích được
A11: Tiêu chí | B11: Trọng số | C11: Chuẩn đạt · Điểm 3 | D11: Dấu hiệu tốt · Điểm 4 | E11: Điểm 1–4 | F11: Evidence & nhận xét | G11: Quy đổi
A12: Chức năng cốt lõi | B12: 20 | C12: Happy path và phần lớn edge case đúng | D12: Đủ flow, đúng edge case, ổn định | G12: =IF(E12="",0,B12*E12/4) -> 0
A13: JavaScript & logic | B13: 10 | C13: Logic đúng, có vài điểm có thể đơn giản | D13: Logic rõ, data transform đúng, immutable nhất quán | G13: =IF(E13="",0,B13*E13/4) -> 0
A14: Kiến trúc React | B14: 15 | C14: Cấu trúc hợp lý, ít coupling | D14: Component/state boundaries rõ, composition tốt | G14: =IF(E14="",0,B14*E14/4) -> 0
A15: State & data fetching | B15: 12 | C15: Fetch/state đúng, error handling cơ bản | D15: Đủ loading/empty/error/race/cache hợp lý | G15: =IF(E15="",0,B15*E15/4) -> 0
A16: UX & responsive | B16: 10 | C16: Dùng được, layout ổn ở viewport chính | D16: Flow mượt, feedback rõ, responsive tốt | G16: =IF(E16="",0,B16*E16/4) -> 0
A17: Accessibility & security | B17: 8 | C17: Label/semantic chính đạt, không lộ secret | D17: Keyboard/focus/semantic tốt, không có pattern nguy hiểm | G17: =IF(E17="",0,B17*E17/4) -> 0
A18: Testing | B18: 10 | C18: Có test logic/UI cho flow chính | D18: Critical flow + error path, test bền vững | G18: =IF(E18="",0,B18*E18/4) -> 0
A19: Code quality & Git | B19: 10 | C19: Code đọc được, lint/build pass | D19: Tên rõ, module gọn, lint pass, commit/PR tốt | G19: =IF(E19="",0,B19*E19/4) -> 0
A20: README, demo & ownership | B20: 5 | C20: README đủ chạy; demo flow chính | D20: Setup/decision/known issues rõ; demo và Q&A tốt | G20: =IF(E20="",0,B20*E20/4) -> 0
A22: TỔNG TRỌNG SỐ | B22: ĐIỂM TỐI ĐA | C22: =SUM(B12:B20) -> 100 | D22: =SUM(B12:B20) -> 100

Sheet TỰ SEARCH
A1: TỰ SEARCH ĐỂ HỌC NHANH HƠN
A2: Tìm đúng triệu chứng · ưu tiên tài liệu chính thống · tạo ví dụ tối thiểu · ghi lại nguyên nhân và cách kiểm chứng
A4: 01 · MÔ TẢ | C4: 02 · SEARCH | E4: 03 · KIỂM CHỨNG
A5: Ghi đúng error, hành vi mong muốn và hành vi thực tế. | C5: Dùng tiếng Anh, thêm tên API/framework và official docs. | E5: Tạo ví dụ nhỏ, dự đoán kết quả rồi tự chạy và giải thích.
A8: Nhóm | B8: Khi nào dùng | C8: Mẫu từ khóa search | D8: Kết quả cần rút ra | E8: Dấu hiệu học sai hướng | F8: Nguồn ưu tiên
A9: Cú pháp | B9: Không hiểu khái niệm | C9: <concept> JavaScript MDN guide examples | D9: Định nghĩa → ví dụ nhỏ → edge case → tự chạy console | E9: Blog chỉ đưa snippet không giải thích | F9: https://developer.mozilla.org/en-US/docs/Web/JavaScript/Guide
A10: Debug | B10: Gặp thông báo lỗi | C10: <exact error message> JavaScript MDN / Stack Overflow | D10: Đọc loại lỗi + dòng đầu stack + tạo minimal reproduction | E10: Copy fix trước khi hiểu nguyên nhân | F10: https://developer.mozilla.org/en-US/docs/Web/JavaScript/Reference/Global_Objects/Error
A11: Array | B11: Chọn method | C11: JavaScript <map/filter/reduce/find/some/every> when to use | D11: Input/output, có mutate không, early stop không | E11: Dùng reduce cho mọi thứ | F11: https://developer.mozilla.org/en-US/docs/Web/JavaScript/Reference/Global_Objects/Array
A12: Object | B12: Update nested data | C12: JavaScript immutable nested object update spread shallow copy | D12: Phân biệt shallow/deep, giữ reference không đổi ở nhánh không sửa | E12: JSON stringify để clone mọi dữ liệu | F12: https://developer.mozilla.org/en-US/docs/Glossary/Shallow_copy
A13: Function | B13: Closure khó hiểu | C13: JavaScript closure lexical scope practical example MDN | D13: Vẽ scope chain, dự đoán output rồi chạy | E13: Học thuộc định nghĩa không viết ví dụ | F13: https://developer.mozilla.org/en-US/docs/Web/JavaScript/Guide/Closures
A14: Async | B14: Sai thứ tự log | C14: JavaScript event loop microtask macrotask promise setTimeout | D14: Vẽ call stack/queues theo từng bước | E14: Chỉ nhớ Promise trước timeout | F14: https://developer.mozilla.org/en-US/docs/Web/JavaScript/Reference/Execution_model
A15: Promise | B15: Nhiều request | C15: Promise.all vs allSettled fail fast use cases | D15: So sánh error semantics và thứ tự kết quả | E15: Chạy tuần tự không cần thiết | F15: https://developer.mozilla.org/en-US/docs/Web/JavaScript/Reference/Global_Objects/Promise
A16: Fetch | B16: API trả 404 không vào catch | C16: fetch does not reject HTTP error response ok MDN | D16: Kiểm tra response.ok/status trước parse | E16: Catch chung và báo Network error sai | F16: https://developer.mozilla.org/en-US/docs/Web/API/Fetch_API/Using_Fetch
A17: HTTP | B17: Không hiểu endpoint | C17: HTTP method status code REST CRUD MDN | D17: Map use case → method → status → body | E17: Mặc định mọi request là POST | F17: https://developer.mozilla.org/en-US/docs/Web/HTTP
A18: DOM | B18: Render dữ liệu user | C18: textContent vs innerHTML XSS MDN | D18: Ưu tiên textContent/createElement, sanitize nếu bắt buộc HTML | E18: Nhét input vào innerHTML | F18: https://developer.mozilla.org/en-US/docs/Web/API/Node/textContent
A19: Events | B19: Click item động không chạy | C19: JavaScript event delegation bubbling target closest | D19: Listener ở ancestor + closest + contains guard | E19: Gắn lại listener sau mỗi render | F19: https://developer.mozilla.org/en-US/docs/Learn_web_development/Core/Scripting/Event_bubbling
... A38: Code review | B38: PR quá lớn | C38: frontend pull request review checklist correctness readability tests | D38: Review theo risk; comment có severity + lý do + gợi ý | E38: Chỉ bắt style/naming | F38: https://google.github.io/eng-practices/review/reviewer/
